Workbook

Sheet Data
A1: Month | B1: Statement Tupe | C1: Office Code | D1: Operating Office | E1: Unique Ref No | F1: Policy Number | G1: Endorsement Number | H1: Policy Holder Name | I1: Effective Start Date | J1: Policy Expiry Date | K1: Product Code | L1: Lob Description | M1: Premium | N1: Brock % | O1: Commission | P1: PIBL | Q1: CN | R1: Inst | S1: Name for Updation | T1: HOD | U1: CSC | V1: Invoice No | W1: Bill ID | X1: Allocated Person | Y1: RFQ status(Yes/No) | Z1: RFQ No | AA1: Modification remarks | AB1: Remarks | AC1: Sachin | AD1: reason
A2: Jun'25 | C2: 272300 | D2: DO 21 NEW DELHI | E2: OIC/25-26/927 | F2: 272300/11/2024/109 | G2: 0 | H2: PARIVAR SEVA SANSTHA | I2: 45108 | J2: 45473 | K2: FIR-PRD-010 | L2: ORIENTAL BHARAT SOOKSHMA UDYAM SURAKSHA POLICY | M2: 59999 | N2: 20.047001 | O2: 12028 | P2: Delhi | Q2: 441579 | R2: 0 | T2: Hemant Kumar Gupta | U2: Sasank S | V2: GGN/23-24/383 | W2: 3080 | X2: Rushiraj | AB2: Excess | AC2: Updation done in Saiba | AD2: Jun'23
A3: Jun'25 | C3: 510000 | D3: CBRO DELHI | E3: OIC/25-26/928 | F3: 510000/48/2023/1560 | G3: 4 | H3: DENTSU WEBCHUTNEY PRIVATE LIMITED | I3: 44964 | J3: 45291 | K3: MIST-PRD-890 | L3: GROUP MEDICLAIM -TAILORMADE-RISK FLOATER | M3: 15137 | N3: 5 | O3: 756.85 | P3: Delhi | Q3: 430685 | R3: NE | T3: Amit Pandey | U3: Niladri Mangal Choudhury | V3: GGN/23-24/384 | W3: 3081 | X3: Rushiraj | AC3: NE | AD3: Jun'23
A4: Jun'25 | C4: 540000 | D4: CBO BANGALORE | E4: OIC/25-26/929 | F4: 421300/48/2023/1166 | G4: 5 | H4: ATRIA CONVERGENCE TECHNOLOGIES LIMITED | I4: 44896 | J4: 45260 | K4: MIST-PRD-890 | L4: GROUP MEDICLAIM -TAILORMADE-RISK FLOATER | M4: -6720 | N4: 7.5 | O4: -504 | P4: Bangalore | Q4: 414344 | R4: E5 | T4: Jayachitra M | U4: Vinod Kumar Heggadadevanapura Thammaiah | V4: BLR/23-24/183 | W4: 3123 | X4: Rushiraj | AC4: Updation done in Saiba | AD4: Jun'23
A5: Jun'25 | C5: 510000 | D5: CBRO DELHI | E5: OIC/25-26/930 | F5: 510000/48/2023/1556 | G5: 4 | H5: DENTSU AEGIS NETWORK INDIA PRIVATE LIMITED | I5: 44938 | J5: 45291 | K5: MIST-PRD-890 | L5: GROUP MEDICLAIM -TAILORMADE-RISK FLOATER | M5: 36689 | N5: 5 | O5: 1834.45 | P5: Delhi | Q5: 430587 | R5: NE | T5: Amit Pandey | U5: Niladri Mangal Choudhury | V5: GGN/23-24/384 | W5: 3081 | X5: Rushiraj | AC5: NE | AD5: Jun'23
A6: Jun'25 | C6: 222105 | D6: KANPUR DEHAT | E6: OIC/25-26/931 | F6: 222105/48/2024/580 | G6: 0 | H6: SACHIN MALIK, | I6: 45098 | J6: 45463 | K6: MIST-PRD-943 | L6: HAPPY FAMILY FLOATER POLICY-2021 | M6: 24849 | N6: 14.998591 | O6: 3000 | P6: Delhi | Q6: 441057 | R6: 0 | T6: Kushal Bhatia | U6: Navneet Arora | V6: GGN/23-24/381 | W6: 3078 | X6: Rushiraj | AC6: Updation done in Saiba | AD6: Jun'23
A7: Jun'25 | C7: 540000 | D7: CBO BANGALORE | E7: OIC/25-26/932 | F7: 421300/48/2023/1048 | G7: 7 | H7: WAFER SPACE SEMICONDUCTOR TECHNOLOGIES PVT LTD | I7: 44812 | J7: 45176 | K7: MIST-PRD-890 | L7: GROUP MEDICLAIM -TAILORMADE-RISK FLOATER | M7: 10358 | N7: 7.5 | O7: 776.85 | P7: Bangalore | Q7: 404320 | R7: NE | T7: Jaya Chitra.M | U7: Deep Shikha | V7: BLR/23-24/183 | W7: 3123 | X7: Rushiraj | AC7: NE | AD7: Jun'23
A8: Jun'25 | C8: 510000 | D8: CBRO DELHI | E8: OIC/25-26/933 | F8: 510000/11/2024/117 | G8: 0 | H8: JCB INDIA LIMITED | I8: 45078 | J8: 45443 | K8: FIR-PRD-009 | L8: ORIENTAL BHARAT LAGHU UDYAM SURAKSHA POLICY | M8: 893665 | N8: 15.352397 | O8: 137199 | P8: Delhi | Q8: NE | R8: NE | T8: Darvesh Panchal | U8: Rohit Kumar Mehndiratta | V8: GGN/23-24/384 | W8: 3081 | X8: Rushiraj | Y8: 215079 | Z8: Yes | AC8: RFQ | AD8: Jun'23
A9: Jun'25 | C9: 132000 | D9: DO JOGESHWARI | E9: OIC/25-26/934 | F9: 132000/11/2022/413 | G9: 3 | H9: Allied Blender & Distillers Pvt Ltd | I9: 44441 | J9: 44805 | K9: FIR-PRD-009 | L9: ORIENTAL BHARAT LAGHU UDYAM SURAKSHA POLICY | M9: -45897 | N9: 10.813343 | O9: -4963 | P9: Mumbai | Q9: 360481 | R9: NE | T9: Susmeet Kaur | U9: Pooja Yadav | V9: MUM/C/23-24/41 | W9: 3100 | X9: Rushiraj | AC9: NE | AD9: Jun'23
A10: Jun'25 | C10: 212203 | D10: CBO 13 N-34 C.PLACE | E10: OIC/25-26/935 | F10: 212203/31/2024/619 | G10: 0 | H10: NHPC LIMITED | I10: 45093 | J10: 45458 | K10: MOT-PRD-015 | L10: STANDALONE OWN DAMAGE(OD)-PRIVATE CAR | M10: 8935 | N10: 14.997202 | O10: 1340 | P10: Delhi | Q10: 443967 | R10: 0 | T10: Saurabh Dwivedi | U10: Mohit Mendiratta | V10: GGN/23-24/378 | W10: 3075 | X10: Rushiraj | AC10: Updation done in Saiba | AD10: Jun'23
A11: Jun'25 | C11: 212200 | D11: NEW DELHI DO 10 | E11: OIC/25-26/936 | F11: 212200/48/2024/267 | G11: 0 | H11: EXCEL PACK PVT LTD | I11: 45090 | J11: 45455 | K11: MIST-PRD-753 | L11: BURGLARY FLOATER | M11: 270 | N11: 12.592593 | O11: 34 | P11: Delhi | Q11: NE | R11: NE | T11: Aradhana Dwivedi | U11: Amit Wali | V11: GGN/23-24/377 | W11: 3074 | X11: Rushiraj | Z11: No | AC11: NE | AD11: Jun'23
A12: Jun'25 | C12: 510000 | D12: CBRO DELHI | E12: OIC/25-26/937 | F12: 510000/48/2023/1556 | G12: 3 | H12: DENTSU AEGIS NETWORK INDIA PRIVATE LIMITED | I12: 44938 | J12: 45291 | K12: MIST-PRD-890 | L12: GROUP MEDICLAIM -TAILORMADE-RISK FLOATER | M12: 63472 | N12: 5 | O12: 3173.6 | P12: Delhi | Q12: 430587 | R12: NE | T12: Amit Pandey | U12: Niladri Mangal Choudhury | V12: GGN/23-24/384 | W12: 3081 | X12: Rushiraj | AC12: NE | AD12: Jun'23
A13: Jun'25 | C13: 163600 | D13: DO IV PUNE | E13: OIC/25-26/938 | F13: 163600/21/2024/3/0001 | G13: 0 | H13: RATHI DYE CHEM (P) LTD | I13: 45078 | J13: 45443 | K13: MC-PRD-015 | L13: MARINE CARGO - OPEN COVER | M13: 9789 | N13: 20.002043 | O13: 1958 | P13: Pune | Q13: NE | R13: NE | T13: Smita Lokapure | U13: Vishal Sushil Pachisia | V13: PUN/23-24/49 | W13: 3090 | X13: Rushiraj | Z13: No | AC13: NE | AD13: Jun'23
A14: Jun'25 | C14: 215600 | D14: DO 4 NEW DELHI | E14: OIC/25-26/946 | F14: 215600/48/2023/1883 | G14: 12 | H14: HCL INFOSYSTEMS LTD | I14: 44835 | J14: 45199 | K14: MIST-PRD-890 | L14: GROUP MEDICLAIM -TAILORMADE-RISK FLOATER | M14: 1154835 | N14: 7.6434296 | O14: 88269 | P14: Delhi | Q14: 405703 | R14: M3 | T14: Abhishek Sharma | U14: Ishita Sharma | V14: GGN/23-24/379 | W14: 3076 | X14: Rushiraj | AC14: NE | AD14: Jun'23
A15: Jun'25 | C15: 510000 | D15: CBRO DELHI | E15: OIC/25-26/939 | F15: 510000/31/2024/47 | G15: 0 | H15: JCB INDIA LIMITED | I15: 45105 | J15: 45470 | K15: MOT-PRD-006 | L15: MISCELANEOUS CLASS D VEHICLES | M15: 10317 | N15: 12.493942 | O15: 1289 | P15: Delhi | Q15: 444639 | R15: 0 | T15: Tejinder Pal Singh | U15: Pushpinder Kaur | V15: GGN/23-24/384 | W15: 3081 | X15: Rushiraj | Z15: No | AC15: Updation Done in Saiba | AD15: Jun'23
A16: Jun'25 | C16: 222105 | D16: KANPUR DEHAT | E16: OIC/25-26/941 | F16: 222105/48/2024/512 | G16: 0 | H16: JAWAID ASHRAF | I16: 45099 | J16: 45464 | K16: MIST-PRD-943 | L16: HAPPY FAMILY FLOATER POLICY-2021 | M16: 84513 | N16: 5.0004141 | O16: 4226 | P16: Delhi | Q16: 440111 | R16: 0 | T16: Kushal Bhatia | U16: Navneet Arora | V16: GGN/23-24/381 | W16: 3078 | X16: Rushiraj | AB16: Part | AC16: Updation done in Saiba | AD16: Jun'23
A17: Jun'25 | C17: 510000 | D17: CBRO DELHI | E17: OIC/25-26/942 | F17: 510000/48/2023/614 | G17: 10 | H17: SUTHERLAND HEALTHCARE SOLUTIONS PRIVATE LIMITED | I17: 44675 | J17: 45039 | K17: MIST-PRD-890 | L17: GROUP MEDICLAIM -TAILORMADE-RISK FLOATER | M17: -1892 | N17: 2.4841438 | O17: -47 | P17: Chennai | Q17: 398821 | R17: NE | T17: Payal Batra | U17: Aas Mohammad | V17: GGN/23-24/384 | W17: 3081 | X17: Rushiraj | AC17: NE | AD17: Jun'23
A18: Jun'25 | C18: 510000 | D18: CBRO DELHI | E18: OIC/25-26/943 | F18: 510000/48/2023/613 | G18: 12 | H18: SUTHERLAND GLOBAL SERVICES PVT LTD | I18: 44675 | J18: 45039 | K18: MIST-PRD-890 | L18: GROUP MEDICLAIM -TAILORMADE-RISK FLOATER | M18: -7456 | N18: 2.4946352 | O18: -186 | P18: Chennai | Q18: 398825 | R18: NE | T18: Payal Batra | U18: Aas Mohammad | V18: GGN/23-24/384 | W18: 3081 | X18: Rushiraj | AC18: NE | AD18: Jun'23
A19: Jun'25 | C19: 212203 | D19: CBO 13 N-34 C.PLACE | E19: OIC/25-26/944 | F19: 212203/31/2024/766 | G19: 0 | H19: EXPORT CREDIT GUARANTEE CORPORATION | I19: 45111 | J19: 45476 | K19: MOT-PRD-015 | L19: STANDALONE OWN DAMAGE(OD)-PRIVATE CAR | M19: 8111 | N19: 14.991986 | O19: 1216 | P19: Delhi | Q19: NE | R19: NE | T19: Suspense | U19: Suspense | V19: GGN/23-24/378 | W19: 3075 | X19: Rushiraj | Z19: No | AC19: NE | AD19: Jun'23
A20: Jun'25 | C20: 421300 | D20: DO 3 BANGALORE | E20: OIC/25-26/945 | F20: 421300/48/2024/482 | G20: 0 | H20: SSP INDIA PRIVATE LIMITED | I20: 45084 | J20: 45449 | K20: MIST-PRD-890 | L20: GROUP MEDICLAIM -TAILORMADE-RISK FLOATER | M20: 2040783 | N20: 7.0000093 | O20: 142855 | P20: Delhi | Q20: 438851 | R20: 0 | T20: Rajiv Choudhary | U20: Ashwini Kumar Srivastava | V20: BLR/23-24/173 | W20: 3066 | X20: Rushiraj | AC20: Updation done in Saiba | AD20: Jun'23
A21: Jun'25 | C21: 111900 | D21: MCDO 14 | E21: OIC/25-26/1295 | F21: 111900/22/2023/895 | G21: 1 | H21: JAYDEEP ASSOCIATES PVT LTD VESSEL: MV SIDDHIVINAYAK II REGNOGMB/NLK/97 YOB: 2023 | I21: 45016 | J21: 45381 | K21: MH-PRD-003 | L21: INLAND VESSELS | M21: 83250 | N21: 11.5003 | O21: 9574 | P21: Mumbai | Q21: 428435 | R21: E1 | T21: Lakshmanan Subramanian Iyer | U21: Saikumar G Shirwatkar | V21: MUM/23-24/568 | W21: 3086 | X21: Rushiraj | AC21: Updation Done in Saiba | AD21: Jun'23
A22: Jun'25 | C22: 510000 | D22: CBRO DELHI | E22: OIC/25-26/947 | F22: 510000/48/2024/423 | G22: 0 | H22: ARTEMIS MEDICARE SERVICES LIMITED | I22: 45090 | J22: 45454 | K22: MIST-PRD-047 | L22: FIDELITY GUARANTEE | M22: 610 | N22: 12.459016 | O22: 76 | P22: Delhi | Q22: 441895 | R22: 0 | T22: Hemant Kumar Gupta | U22: Namit Malhotra | V22: GGN/23-24/384 | W22: 3081 | X22: Rushiraj | AA22: Premium Mismatched | AC22: Modification | AD22: Jun'23
A23: Jun'25 | C23: 111900 | D23: MCDO 14 | E23: OIC/25-26/948 | F23: 111900/22/2024/266 | G23: 0 | H23: 3K MARINE SERVICES | I23: 45104 | J23: 45469 | K23: MH-PRD-003 | L23: INLAND VESSELS | M23: 43125 | N23: 14.998261 | O23: 6468 | P23: Mumbai | Q23: NE | R23: NE | T23: Lakshmanan Subramanian Iyer | U23: Saikumar G Shirwatkar | V23: MUM/23-24/568 | W23: 3086 | X23: Rushiraj | Z23: No | AC23: NE | AD23: Jun'23
A24: Jun'25 | C24: 212203 | D24: CBO 13 N-34 C.PLACE | E24: OIC/25-26/949 | F24: 212203/48/2024/581 | G24: 0 | H24: QRG ENTERPRISES LTD | I24: 45039 | J24: 45382 | K24: MIST-PRD-052 | L24: MONEY INSURANCE | M24: 1178 | N24: 16.468591 | O24: 194 | P24: Delhi | Q24: NE | R24: NE | T24: Vineet Khattar | U24: Sumit Gupta | V24: GGN/23-24/378 | W24: 3075 | X24: Rushiraj | Z24: No | AC24: NE | AD24: Jun'23
A25: Jun'25 | C25: 212203 | D25: CBO 13 N-34 C.PLACE | E25: OIC/25-26/950 | F25: 212203/31/2024/559 | G25: 0 | H25: LESSEE:AC(HQ) SOUTH DELHI M CORP | I25: 45084 | J25: 45449 | K25: MOT-PRD-001 | L25: PRIVATE CAR | M25: 8706 | N25: 13.266713 | O25: 990 | P25: Delhi | Q25: 443804 | R25: 0 | T25: Saurabh Dwivedi | U25: Mohit Mendiratta | V25: GGN/23-24/378 | W25: 3075 | X25: Rushiraj | AA25: TP Brok % need to modify | AC25: Modification | AD25: Jun'23
A26: Jun'25 | C26: 212203 | D26: CBO 13 N-34 C.PLACE | E26: OIC/25-26/951 | F26: 212203/31/2024/687 | G26: 0 | H26: LESSEE POWER GRID CORPORATION OF INDIA LTD | I26: 45097 | J26: 45462 | K26: MOT-PRD-012 | L26: PRIVATE CAR-(3 Years) | M26: 9682 | N26: 14.996901 | O26: 1452 | P26: Delhi | Q26: Contra | R26: Contra | T26: Saurabh Dwivedi | U26: Mohit Mendiratta | V26: GGN/23-24/378 | W26: 3075 | X26: Rushiraj | AC26: Contra | AD26: Jun'23
A27: Jun'25 | C27: 272200 | D27: DO 3 NEW DELHI | E27: OIC/25-26/952 | F27: 272200/31/2024/363 | G27: 0 | H27: JCB INDIA LTD | I27: 45091 | J27: 45456 | K27: MOT-PRD-006 | L27: MISCELANEOUS CLASS D VEHICLES | M27: 12981 | N27: 12.495185 | O27: 1622 | P27: Delhi | Q27: NE | R27: NE | T27: Tejinder Pal Singh | U27: Pushpinder Kaur | V27: GGN/23-24/382 | W27: 3079 | X27: Rushiraj | Z27: No | AC27: NE | AD27: Jun'23
A28: Jun'25 | C28: 212203 | D28: CBO 13 N-34 C.PLACE | E28: OIC/25-26/953 | F28: 212203/31/2024/636 | G28: 0 | H28: MINISTRY OF INFO & BROADCASTING | I28: 45095 | J28: 45460 | K28: MOT-PRD-001 | L28: PRIVATE CAR | M28: 9224 | N28: 13.356461 | O28: 1232 | P28: Delhi | Q28: 443826 | R28: 0 | T28: Saurabh Dwivedi | U28: Mohit Mendiratta | V28: GGN/23-24/378 | W28: 3075 | X28: Rushiraj | AA28: TP Brok % need to modify | AC28: Modification | AD28: Jun'23
A29: Jun'25 | C29: 212203 | D29: CBO 13 N-34 C.PLACE | E29: OIC/25-26/954 | F29: 212203/31/2024/596 | G29: 0 | H29: EAST DELHI MUNICIPAL CORPORATION | I29: 45088 | J29: 45453 | K29: MOT-PRD-001 | L29: PRIVATE CAR | M29: 8512 | N29: 13.228383 | O29: 1126 | P29: Delhi | Q29: 443822 | R29: 0 | T29: Saurabh Dwivedi | U29: Mohit Mendiratta | V29: GGN/23-24/378 | W29: 3075 | X29: Rushiraj | AA29: TP Brok % need to modify | AC29: Modification | AD29: Jun'23
A30: Jun'25 | C30: 212203 | D30: CBO 13 N-34 C.PLACE | E30: OIC/25-26/955 | F30: 212203/31/2024/662 | G30: 0 | H30: DIRECTORATE OF TRANSPORT | I30: 45099 | J30: 45464 | K30: MOT-PRD-001 | L30: PRIVATE CAR | M30: 8522 | N30: 13.224595 | O30: 1127 | P30: Delhi | Q30: 443832 | R30: 0 | T30: Saurabh Dwivedi | U30: Mohit Mendiratta | V30: GGN/23-24/378 | W30: 3075 | X30: Rushiraj | AA30: TP Brok % need to modify | AC30: Modification | AD30: Jun'23
A31: Jun'25 | C31: 215600 | D31: DO 4 NEW DELHI | E31: OIC/25-26/956 | F31: 215600/48/2024/666 | G31: 0 | H31: Lumax Ancillary Ltd | I31: 45017 | J31: 45382 | K31: MIST-PRD-061 | L31: All RISK | M31: 626 | N31: 12.460064 | O31: 78 | P31: Delhi | Q31: 430568 | R31: 0 | T31: Rohit Kumar Mendiratta | U31: Prince Tayal | V31: GGN/23-24/379 | W31: 3076 | X31: Rushiraj | AC31: Updation done in Saiba | AD31: Jun'23
A32: Jun'25 | C32: 212203 | D32: CBO 13 N-34 C.PLACE | E32: OIC/25-26/957 | F32: 212203/31/2024/556 | G32: 0 | H32: LESSEE:AC(HQ) SOUTH DELHI M CORP | I32: 45084 | J32: 45449 | K32: MOT-PRD-001 | L32: PRIVATE CAR | M32: 3358 | N32: 10.48243 | O32: 352 | P32: Delhi | Q32: 443801 | R32: 0 | T32: Saurabh Dwivedi | U32: Mohit Mendiratta | V32: GGN/23-24/378 | W32: 3075 | X32: Rushiraj | AA32: TP Brok % need to modify | AC32: Modification | AD32: Jun'23
A33: Jun'25 | C33: 510000 | D33: CBRO DELHI | E33: OIC/25-26/958 | F33: 510000/48/2023/765 | G33: 6 | H33: Sutherland Global Services Private Limited | I33: 44713 | J33: 45077 | K33: MIST-PRD-890 | L33: GROUP MEDICLAIM -TAILORMADE-RISK FLOATER | M33: -1036 | N33: 3 | O33: -31.08 | P33: Chennai | Q33: 418715 | R33: NE | T33: Payal Batra | U33: Aas Mohammad | V33: GGN/23-24/384 | W33: 3081 | X33: Rushiraj | AC33: NE | AD33: Jun'23
A34: Jun'25 | C34: 411700 | D34: DO 7 CHENNAI | E34: OIC/25-26/959 | F34: 411700/48/2023/2426 | G34: 8 | H34: FINANCIAL SOFTWARE & SYSTEMS (P) LTD | I34: 44835 | J34: 45199 | K34: MIST-PRD-890 | L34: GROUP MEDICLAIM -TAILORMADE-RISK FLOATER | M34: 4579 | N34: 1 | O34: 45.79 | P34: Chennai | Q34: 408012 | R34: E7 | T34: Meenakshi Menon | U34: Sudha.S | V34: CHN/23-24/123 | W34: 3069 | X34: Rushiraj | AC34: Saiba Error | AD34: Jun'23
A35: Jun'25 | C35: 510000 | D35: CBRO DELHI | E35: OIC/25-26/960 | F35: 510000/48/2023/392 | G35: 12 | H35: NORTHERN MARINE MANAGEMENT (INDIA) PVTLTD | I35: 44681 | J35: 45045 | K35: MIST-PRD-890 | L35: GROUP MEDICLAIM -TAILORMADE-RISK FLOATER | M35: 1330 | N35: 5 | O35: 66.5 | P35: Mumbai | Q35: 382317 | R35: E11 | T35: Ashita Lotia | U35: Arpita R Kochrekar | V35: GGN/23-24/384 | W35: 3081 | X35: Rushiraj | AC35: Updation done in Saiba | AD35: Jun'23
A36: Jun'25 | C36: 510000 | D36: CBRO DELHI | E36: OIC/25-26/961 | F36: 510000/48/2023/1559 | G36: 3 | H36: DENTSU NETWORK ADVERTISING PRIVATE LIMITED | I36: 44964 | J36: 45291 | K36: MIST-PRD-890 | L36: GROUP MEDICLAIM -TAILORMADE-RISK FLOATER | M36: -31233 | N36: 5 | O36: -1561.65 | P36: Delhi | Q36: 430593 | R36: NE | T36: Amit Pandey | U36: Niladri Mangal Choudhury | V36: GGN/23-24/384 | W36: 3081 | X36: Rushiraj | AC36: NE | AD36: Jun'23
A37: Jun'25 | C37: 510000 | D37: CBRO DELHI | E37: OIC/25-26/962 | F37: 510000/48/2024/417 | G37: 0 | H37: ARTEMIS MEDICARE SERVICES LIMITED | I37: 45090 | J37: 45454 | K37: MIST-PRD-025 | L37: PLATE GLASS INSURANCE | M37: 625 | N37: 12.48 | O37: 78 | P37: Delhi | Q37: 441894 | R37: 0 | T37: Hemant Kumar Gupta | U37: Namit Malhotra | V37: GGN/23-24/384 | W37: 3081 | X37: Rushiraj | AB37: Excess | AC37: Updation done in Saiba | AD37: Jun'23
A38: Jun'25 | C38: 510000 | D38: CBRO DELHI | E38: OIC/25-26/963 | F38: 510000/48/2023/1559 | G38: 4 | H38: DENTSU NETWORK ADVERTISING PRIVATE LIMITED | I38: 44964 | J38: 45291 | K38: MIST-PRD-890 | L38: GROUP MEDICLAIM -TAILORMADE-RISK FLOATER | M38: -16143 | N38: 5 | O38: -807.15 | P38: Delhi | Q38: 430593 | R38: NE | T38: Amit Pandey | U38: Niladri Mangal Choudhury | V38: GGN/23-24/384 | W38: 3081 | X38: Rushiraj | AC38: NE | AD38: Jun'23
A39: Jun'25 | C39: 510000 | D39: CBRO DELHI | E39: OIC/25-26/964 | F39: 510000/31/2024/41 | G39: 0 | H39: JCB INDIA LTD | I39: 45093 | J39: 45458 | K39: MOT-PRD-006 | L39: MISCELANEOUS CLASS D VEHICLES | M39: 13058 | N39: 12.498085 | O39: 1632 | P39: Pune | Q39: NE | R39: NE | T39: Azmi Raza | U39: Salman Shaikh | V39: GGN/23-24/384 | W39: 3081 | X39: Rushiraj | Z39: No | AC39: NE | AD39: Jun'23
A40: Jun'25 | C40: 212203 | D40: CBO 13 N-34 C.PLACE | E40: OIC/25-26/965 | F40: 212203/31/2024/530 | G40: 0 | H40: EAST DELHI MUNICIPAL CORPORATION | I40: 45081 | J40: 45446 | K40: MOT-PRD-001 | L40: PRIVATE CAR | M40: 8512 | N40: 0 | O40: 0 | P40: Delhi | Q40: 443787 | R40: 0 | T40: Saurabh Dwivedi | U40: Mohit Mendiratta | V40: GGN/23-24/378 | W40: 3075 | X40: Rushiraj | AB40: Part | AC40: Updation done in Saiba | AD40: Jun'23
...

Sheet Sheet3
A1: Month | B1: (All) | D1: Row Labels | E1: Sum of Commission | L1: Remarks
D2: BLR/23-24/100 | E2: 1586835.8 | F2: =VLOOKUP(D2,'[1]Sales Register'!$E:$I,5,0) -> 1586835.8 | G2: =E2-F2 -> 0 | I2: Done | J2: =VLOOKUP(D2,Data!V:AD,9,0) -> #N/A
A3: Row Labels | B3: Sum of Commission | D3: BLR/23-24/101 | E3: 119553.1 | F3: =VLOOKUP(D3,'[1]Sales Register'!$E:$I,5,0) -> 119553.1 | G3: =E3-F3 -> 0 | I3: Done | J3: =VLOOKUP(D3,Data!V:AD,9,0) -> #N/A
A4: BLR/23-24/100 | B4: 1586835.8 | D4: BLR/23-24/102 | E4: 481686.51 | F4: =VLOOKUP(D4,'[1]Sales Register'!$E:$I,5,0) -> 481686.51 | G4: =E4-F4 -> 0 | I4: Done | J4: =VLOOKUP(D4,Data!V:AD,9,0) -> #N/A
A5: BLR/23-24/101 | B5: 119553.1 | D5: BLR/23-24/103 | E5: 831 | F5: =VLOOKUP(D5,'[1]Sales Register'!$E:$I,5,0) -> 831 | G5: =E5-F5 -> 0 | I5: Done | J5: =VLOOKUP(D5,Data!V:AD,9,0) -> #N/A
A6: BLR/23-24/102 | B6: 481686.51 | D6: BLR/23-24/104 | E6: 2362 | F6: =VLOOKUP(D6,'[1]Sales Register'!$E:$I,5,0) -> 2362 | G6: =E6-F6 -> 0 | I6: Done | J6: =VLOOKUP(D6,Data!V:AD,9,0) -> #N/A
A7: BLR/23-24/103 | B7: 831 | D7: BLR/23-24/172 | E7: 221395.68 | F7: =VLOOKUP(D7,'[1]Sales Register'!$E:$I,5,0) -> 221395.68 | G7: =E7-F7 -> 0 | I7: Done | J7: =VLOOKUP(D7,Data!V:AD,9,0) -> Jun'23
A8: BLR/23-24/104 | B8: 2362 | D8: BLR/23-24/173 | E8: 132287 | F8: =VLOOKUP(D8,'[1]Sales Register'!$E:$I,5,0) -> 132287 | G8: =E8-F8 -> 0 | I8: Done | J8: =VLOOKUP(D8,Data!V:AD,9,0) -> Jun'23
A9: BLR/23-24/172 | B9: 221395.68 | D9: BLR/23-24/174 | E9: 1357 | F9: =VLOOKUP(D9,'[1]Sales Register'!$E:$I,5,0) -> 1357 | G9: =E9-F9 -> 0 | I9: Done | J9: =VLOOKUP(D9,Data!V:AD,9,0) -> Jun'23
A10: BLR/23-24/173 | B10: 132287 | D10: BLR/23-24/183 | E10: 265064.66 | F10: =VLOOKUP(D10,'[1]Sales Register'!$E:$I,5,0) -> 265064.66 | G10: =E10-F10 -> 0 | I10: Done | J10: =VLOOKUP(D10,Data!V:AD,9,0) -> Jun'23
A11: BLR/23-24/174 | B11: 1357 | D11: BLR/23-24/204 | E11: 606019.38 | F11: =VLOOKUP(D11,'[1]Sales Register'!$E:$I,5,0) -> 606019.38 | G11: =E11-F11 -> 0 | I11: Done | J11: =VLOOKUP(D11,Data!V:AD,9,0) -> #N/A
A12: BLR/23-24/183 | B12: 265064.66 | D12: BLR/23-24/205 | E12: 765269 | F12: =VLOOKUP(D12,'[1]Sales Register'!$E:$I,5,0) -> 765269 | G12: =E12-F12 -> 0 | I12: Done | J12: =VLOOKUP(D12,Data!V:AD,9,0) -> #N/A
A13: BLR/23-24/204 | B13: 606019.38 | D13: BLR/23-24/206 | E13: 11881.43 | F13: =VLOOKUP(D13,'[1]Sales Register'!$E:$I,5,0) -> 11881.43 | G13: =E13-F13 -> 0 | I13: Done | J13: =VLOOKUP(D13,Data!V:AD,9,0) -> #N/A
A14: BLR/23-24/205 | B14: 765269 | D14: BLR/23-24/62 | E14: 3186.56 | F14: =VLOOKUP(D14,'[1]Sales Register'!$E:$I,5,0) -> 3186.56 | G14: =E14-F14 -> 0 | I14: Done | J14: =VLOOKUP(D14,Data!V:AD,9,0) -> #N/A
A15: BLR/23-24/206 | B15: 11881.43 | D15: BLR/23-24/63 | E15: 729671 | F15: =VLOOKUP(D15,'[1]Sales Register'!$E:$I,5,0) -> 729671 | G15: =E15-F15 -> 0 | I15: Done | J15: =VLOOKUP(D15,Data!V:AD,9,0) -> #N/A
... A17: BLR/23-24/63 | B17: 729671 | D17: BLR/23-24/65 | E17: 418800 | F17: =VLOOKUP(D17,'[1]Sales Register'!$E:$I,5,0) -> 418800 | G17: =E17-F17 -> 0 | I17: Done | J17: =VLOOKUP(D17,Data!V:AD,9,0) -> #N/A
A18: BLR/23-24/64 | B18: 374752.63 | D18: BLR/C/23-24/04 | E18: -61632 | F18: =VLOOKUP(D18,'[1]Sales Register'!$E:$I,5,0) -> #N/A | G18: =E18-F18 -> #N/A | H18: =VLOOKUP(D18,'[1]Credit Note Register'!$E:$I,5,0) -> 61632 | I18: Done | J18: =VLOOKUP(D18,Data!V:AD,9,0) -> #N/A
A19: BLR/23-24/65 | B19: 418800 | D19: BLR/C/23-24/07 | E19: -34888 | F19: =VLOOKUP(D19,'[1]Sales Register'!$E:$I,5,0) -> #N/A | G19: =E19-F19 -> #N/A | H19: =VLOOKUP(D19,'[1]Credit Note Register'!$E:$I,5,0) -> 34888 | I19: Done | J19: =VLOOKUP(D19,Data!V:AD,9,0) -> Jun'23
A20: BLR/C/23-24/04 | B20: -61632 | D20: BLR/C/23-24/13 | E20: 1691.9 | F20: =VLOOKUP(D20,'[1]Sales Register'!$E:$I,5,0) -> #N/A | G20: =E20-F20 -> #N/A | H20: =VLOOKUP(D20,'[1]Credit Note Register'!$E:$I,5,0) -> 368.63 | I20: Done | J20: =VLOOKUP(D20,Data!V:AD,9,0) -> #N/A
A21: BLR/C/23-24/07 | B21: -34888 | D21: CHN/23-24/122 | E21: 76800 | F21: =VLOOKUP(D21,'[1]Sales Register'!$E:$I,5,0) -> 76800 | G21: =E21-F21 -> 0 | I21: Done | J21: =VLOOKUP(D21,Data!V:AD,9,0) -> Jun'23
A22: BLR/C/23-24/13 | B22: 1691.9 | D22: CHN/23-24/123 | E22: 34.99 | F22: =VLOOKUP(D22,'[1]Sales Register'!$E:$I,5,0) -> 34.99 | G22: =E22-F22 -> 0 | I22: Done | J22: =VLOOKUP(D22,Data!V:AD,9,0) -> Jun'23
A23: CHN/23-24/122 | B23: 76800 | D23: CHN/23-24/124 | E23: 341.7 | F23: =VLOOKUP(D23,'[1]Sales Register'!$E:$I,5,0) -> 341.7 | G23: =E23-F23 -> 0 | I23: Done | J23: =VLOOKUP(D23,Data!V:AD,9,0) -> Jun'23
A24: CHN/23-24/123 | B24: 34.99 | D24: CHN/23-24/125 | E24: 3855 | F24: =VLOOKUP(D24,'[1]Sales Register'!$E:$I,5,0) -> 3855 | G24: =E24-F24 -> 0 | I24: Done | J24: =VLOOKUP(D24,Data!V:AD,9,0) -> Jun'23
A25: CHN/23-24/124 | B25: 341.7 | D25: CHN/23-24/126 | E25: 3 | F25: =VLOOKUP(D25,'[1]Sales Register'!$E:$I,5,0) -> 3 | G25: =E25-F25 -> 0 | I25: Done | J25: =VLOOKUP(D25,Data!V:AD,9,0) -> Jun'23
A26: CHN/23-24/125 | B26: 3855 | D26: CHN/23-24/127 | E26: 17564 | F26: =VLOOKUP(D26,'[1]Sales Register'!$E:$I,5,0) -> 17564 | G26: =E26-F26 -> 0 | I26: Done | J26: =VLOOKUP(D26,Data!V:AD,9,0) -> Jun'23
A27: CHN/23-24/126 | B27: 3 | D27: CHN/23-24/148 | E27: 11318.37 | F27: =VLOOKUP(D27,'[1]Sales Register'!$E:$I,5,0) -> 4.72 | G27: =VLOOKUP(E27,'[1]Sales Register'!$E:$I,5,0) -> #N/A | H27: =VLOOKUP(D27,'[1]Credit Note Register'!$E:$I,5,0) -> #N/A | I27: Done | J27: =VLOOKUP(D27,Data!V:AD,9,0) -> #N/A
A28: CHN/23-24/127 | B28: 17564 | D28: CHN/23-24/44 | E28: 247 | F28: =VLOOKUP(D28,'[1]Sales Register'!$E:$I,5,0) -> 247 | G28: =E28-F28 -> 0 | I28: Done | J28: =VLOOKUP(D28,Data!V:AD,9,0) -> #N/A
A29: CHN/23-24/148 | B29: 11318.37 | D29: CHN/23-24/45 | E29: 1860.53 | F29: =VLOOKUP(D29,'[1]Sales Register'!$E:$I,5,0) -> 1860.53 | G29: =E29-F29 -> 0 | I29: Done | J29: =VLOOKUP(D29,Data!V:AD,9,0) -> #N/A
A30: CHN/23-24/44 | B30: 247 | D30: CHN/23-24/46 | E30: 1250.39 | F30: =VLOOKUP(D30,'[1]Sales Register'!$E:$I,5,0) -> 1250.39 | G30: =E30-F30 -> 0 | I30: Done | J30: =VLOOKUP(D30,Data!V:AD,9,0) -> #N/A
A31: CHN/23-24/45 | B31: 1860.53 | D31: CHN/23-24/47 | E31: 8217 | F31: =VLOOKUP(D31,'[1]Sales Register'!$E:$I,5,0) -> 8217 | G31: =E31-F31 -> 0 | I31: Done | J31: =VLOOKUP(D31,Data!V:AD,9,0) -> #N/A
A32: CHN/23-24/46 | B32: 1250.39 | D32: CHN/23-24/48 | E32: 923 | F32: =VLOOKUP(D32,'[1]Sales Register'!$E:$I,5,0) -> 923 | G32: =E32-F32 -> 0 | I32: Done | J32: =VLOOKUP(D32,Data!V:AD,9,0) -> #N/A
A33: CHN/23-24/47 | B33: 8217 | D33: CHN/23-24/49 | E33: 48628 | F33: =VLOOKUP(D33,'[1]Sales Register'!$E:$I,5,0) -> 48628 | G33: =E33-F33 -> 0 | I33: Done | J33: =VLOOKUP(D33,Data!V:AD,9,0) -> #N/A
A34: CHN/23-24/48 | B34: 923 | D34: CHN/23-24/63 | E34: 2002.88 | F34: =VLOOKUP(D34,'[1]Sales Register'!$E:$I,5,0) -> 2002.88 | G34: =E34-F34 -> 0 | I34: Done | J34: =VLOOKUP(D34,Data!V:AD,9,0) -> #N/A
A35: CHN/23-24/49 | B35: 48628 | D35: CHN/23-24/64 | E35: 937.6 | F35: =VLOOKUP(D35,'[1]Sales Register'!$E:$I,5,0) -> 937.6 | G35: =E35-F35 -> 0 | I35: Done | J35: =VLOOKUP(D35,Data!V:AD,9,0) -> #N/A
A36: CHN/23-24/63 | B36: 2002.88 | D36: CHN/23-24/65 | E36: 772.35 | F36: =VLOOKUP(D36,'[1]Sales Register'!$E:$I,5,0) -> 772.35 | G36: =E36-F36 -> 0 | I36: Done | J36: =VLOOKUP(D36,Data!V:AD,9,0) -> #N/A
A37: CHN/23-24/64 | B37: 937.6 | D37: CHN/23-24/66 | E37: 1270 | F37: =VLOOKUP(D37,'[1]Sales Register'!$E:$I,5,0) -> 1270 | G37: =E37-F37 -> 0 | I37: Done | J37: =VLOOKUP(D37,Data!V:AD,9,0) -> #N/A
A38: CHN/23-24/65 | B38: 772.35 | D38: CHN/23-24/67 | E38: 201712.91 | F38: =VLOOKUP(D38,'[1]Sales Register'!$E:$I,5,0) -> 201712.91 | G38: =E38-F38 -> 0 | I38: Done | J38: =VLOOKUP(D38,Data!V:AD,9,0) -> #N/A
A39: CHN/23-24/66 | B39: 1270 | D39: CHN/C/23-24/11 | E39: -326.78 | F39: =VLOOKUP(D39,'[1]Sales Register'!$E:$I,5,0) -> #N/A | G39: =E39-F39 -> #N/A | H39: =VLOOKUP(D39,'[1]Credit Note Register'!$E:$I,5,0) -> 326.78 | I39: Done | J39: =VLOOKUP(D39,Data!V:AD,9,0) -> #N/A
A40: CHN/23-24/67 | B40: 201712.91 | D40: CHN/C/23-24/14 | E40: -1128 | F40: =VLOOKUP(D40,'[1]Sales Register'!$E:$I,5,0) -> #N/A | G40: =E40-F40 -> #N/A | H40: =VLOOKUP(D40,'[1]Credit Note Register'!$E:$I,5,0) -> 1128 | I40: Done | J40: =VLOOKUP(D40,Data!V:AD,9,0) -> #N/A
A41: CHN/C/23-24/11 | B41: -326.78 | D41: CHN/C/23-24/24 | E41: -7.65 | F41: =VLOOKUP(D41,'[1]Sales Register'!$E:$I,5,0) -> #N/A | G41: =E41-F41 -> #N/A | H41: =VLOOKUP(D41,'[1]Credit Note Register'!$E:$I,5,0) -> 7.65 | I41: Done | J41: =VLOOKUP(D41,Data!V:AD,9,0) -> Jun'23
...
